<?xml version="1.0" encoding="utf-8"?>
<!-- This URDF was automatically created by SolidWorks to URDF Exporter! Originally created by Stephen Brawner (brawner@gmail.com) 
     Commit Version: 1.6.0-4-g7f85cfe  Build Version: 1.6.7995.38578
     For more information, please see http://wiki.ros.org/sw_urdf_exporter -->
<robot
  name="bumperbot">
  <link name="base_footprint"/>
  <link
    name="base_link">
    <inertial>
      <origin
        xyz="-0.0020098522672192 -0.00277448578669158 0.0152338681517864"
        rpy="0 0 0" />
      <mass
        value="0.091306007508054" />
      <inertia
        ixx="2.35544148873918E-05"
        ixy="8.03602673252866E-08"
        ixz="-1.30819394891215E-07"
        iyy="9.54438344720792E-06"
        iyz="3.13041624472159E-09"
        izz="2.77362876053001E-05" />
    </inertial>
    <visual>
      <origin
        xyz="0 0 0"
        rpy="0 0 0" />
      <geometry>
        <mesh
          filename="package://bumperbot_description/meshes/base_link.STL" />
      </geometry>
      <material
        name="">
        <color
          rgba="0.258823529411765 0.27843137254902 0.301960784313725 1" />
      </material>
    </visual>
    <collision>
      <origin
        xyz="0 0 0"
        rpy="0 0 0" />
      <geometry>
        <mesh
          filename="package://bumperbot_description/meshes/base_link.STL" />
      </geometry>
    </collision>
  </link>
  <joint name="base_joint" type="fixed">
    <parent link="base_footprint"/>
    <child link="base_link" />
    <origin xyz="0 0 0.033" rpy="0 0 0"/>
  </joint>
  <link
    name="wheel_right_link">
    <inertial>
      <origin
        xyz="0.000573251467595751 -0.0137052643929229 0.000358738960939631"
        rpy="0 0 0" />
      <mass
        value="0.0530086090966721" />
      <inertia
        ixx="1.88176298336665E-05"
        ixy="-4.8444933029987E-10"
        ixz="1.88163708851143E-08"
        iyy="3.11510738647764E-05"
        iyz="-6.93560663069607E-11"
        izz="1.8801969558182E-05" />
    </inertial>
    <visual>
      <origin
        xyz="0 0 0"
        rpy="1.57 0 0" />
      <geometry>
        <mesh
          filename="package://bumperbot_description/meshes/wheel_right_link.STL" />
      </geometry>
      <material
        name="">
        <color
          rgba="0.831372549019608 0.670588235294118 0.129411764705882 1" />
      </material>
    </visual>
    <collision>
      <origin
        xyz="0 0 0"
        rpy="1.57 0 0" />
      <geometry>
        <mesh
          filename="package://bumperbot_description/meshes/wheel_right_link.STL" />
      </geometry>
    </collision>
  </link>
  <joint
    name="wheel_right_joint"
    type="continuous">
    <origin
      xyz="0 -0.0701101849418637 0"
      rpy="0 0 0" />
    <parent
      link="base_link" />
    <child
      link="wheel_right_link" />
    <axis
      xyz="0 1 0" />
  </joint>
  <link
    name="wheel_left_link">
    <inertial>
      <origin
        xyz="0.000216638831504246 0.0137052653316193 -0.000640606107818048"
        rpy="0 0 0" />
      <mass
        value="0.0530086043217644" />
      <inertia
        ixx="1.8792911368909E-05"
        ixy="3.31256392204584E-10"
        ixz="-1.14082001662767E-08"
        iyy="3.11510738759073E-05"
        iyz="-3.60499245082192E-10"
        izz="1.88266886146847E-05" />
    </inertial>
    <visual>
      <origin
        xyz="0 0 0"
        rpy="-1.57 0 0" />
      <geometry>
        <mesh
          filename="package://bumperbot_description/meshes/wheel_left_link.STL" />
      </geometry>
      <material
        name="">
        <color
          rgba="0.792156862745098 0.819607843137255 0.933333333333333 1" />
      </material>
    </visual>
    <collision>
      <origin
        xyz="0 0 0"
        rpy="-1.57 0 0" />
      <geometry>
        <mesh
          filename="package://bumperbot_description/meshes/wheel_left_link.STL" />
      </geometry>
    </collision>
  </link>
  <joint
    name="wheel_left_joint"
    type="continuous">
    <origin
      xyz="0 0.0701101849418642 0"
      rpy="0 0 0" />
    <parent
      link="base_link" />
    <child
      link="wheel_left_link" />
    <axis
      xyz="0 1 0" />
  </joint>
  <link
    name="caster_front_link">
    <inertial>
      <origin
        xyz="3.89968128948481E-07 2.40073004698083E-07 0.00219173397061506"
        rpy="0 0 0" />
      <mass
        value="1.44379265037903E-06" />
      <inertia
        ixx="7.23075276010246E-11"
        ixy="-6.10956883467859E-16"
        ixz="2.22849693525031E-15"
        iyy="3.8713793085917E-11"
        iyz="2.93909858781952E-15"
        izz="1.00967486676306E-10" />
    </inertial>
    <visual>
      <origin
        xyz="0 0 0"
        rpy="0 0 0" />
      <geometry>
        <mesh
          filename="package://bumperbot_description/meshes/caster_front_link.STL" />
      </geometry>
      <material
        name="">
        <color
          rgba="1 0 0 1" />
      </material>
    </visual>
    <collision>
      <origin
        xyz="0 0 0"
        rpy="0 0 0" />
      <geometry>
        <mesh
          filename="package://bumperbot_description/meshes/caster_front_link.STL" />
      </geometry>
    </collision>
  </link>
  <joint
    name="caster_front_joint"
    type="fixed">
    <origin
      xyz="0.04755 0 -0.027"
      rpy="0 0 0" />
    <parent
      link="base_link" />
    <child
      link="caster_front_link" />
    <axis
      xyz="0 0 0" />
  </joint>
  <link
    name="caster_rear_link">
    <inertial>
      <origin
        xyz="3.8996812895542E-07 2.40073004698083E-07 0.00219173397061509"
        rpy="0 0 0" />
      <mass
        value="1.44379265037902E-06" />
      <inertia
        ixx="7.23075276010246E-11"
        ixy="-6.10956872363424E-16"
        ixz="2.22849693527207E-15"
        iyy="3.87137930859167E-11"
        iyz="2.939098587861E-15"
        izz="1.00967486676306E-10" />
    </inertial>
    <visual>
      <origin
        xyz="0 0 0"
        rpy="0 0 0" />
      <geometry>
        <mesh
          filename="package://bumperbot_description/meshes/caster_rear_link.STL" />
      </geometry>
      <material
        name="">
        <color
          rgba="0.258823529411765 0.27843137254902 0.301960784313725 1" />
      </material>
    </visual>
    <collision>
      <origin
        xyz="0 0 0"
        rpy="0 0 0" />
      <geometry>
        <mesh
          filename="package://bumperbot_description/meshes/caster_rear_link.STL" />
      </geometry>
    </collision>
  </link>
  <joint
    name="caster_rear_joint"
    type="fixed">
    <origin
      xyz="-0.04755 0 -0.027"
      rpy="0 0 0" />
    <parent
      link="base_link" />
    <child
      link="caster_rear_link" />
    <axis
      xyz="0 0 0" />
  </joint>
  <link
    name="camera_link">
    <inertial>
      <origin
        xyz="-0.0122943599302166 -9.05173297049283E-07 0.00843684900384606"
        rpy="0 0 0" />
      <mass
        value="0.0041086489783227" />
      <inertia
        ixx="3.98797447678453E-07"
        ixy="-8.24558929781979E-11"
        ixz="1.22069699665359E-07"
        iyy="4.18205575812023E-07"
        iyz="-1.01562924198144E-10"
        izz="4.28578734986182E-07" />
    </inertial>
    <visual>
      <origin
        xyz="0 0 0"
        rpy="0 0 0" />
      <geometry>
        <mesh
          filename="package://bumperbot_description/meshes/camera_link.STL" />
      </geometry>
      <material
        name="">
        <color
          rgba="0.792156862745098 0.819607843137255 0.933333333333333 1" />
      </material>
    </visual>
    <collision>
      <origin
        xyz="0 0 0"
        rpy="0 0 0" />
      <geometry>
        <mesh
          filename="package://bumperbot_description/meshes/camera_link.STL" />
      </geometry>
    </collision>
  </link>
  <joint
    name="camera_joint"
    type="fixed">
    <origin
      xyz="0.081561 0 0.067457"
      rpy="0 -0.23739 0" />
    <parent
      link="base_link" />
    <child
      link="camera_link" />
    <axis
      xyz="0 0 0" />
  </joint>
  <link
    name="laser_link">
    <inertial>
      <origin
        xyz="-0.011945780406062 -0.000381929217680526 -0.0170649378129477"
        rpy="0 0 0" />
      <mass
        value="0.073084435549317" />
      <inertia
        ixx="1.96074931730795E-05"
        ixy="-3.62091076640009E-07"
        ixz="4.28230084046735E-07"
        iyy="2.40983835136327E-05"
        iyz="1.50180909250652E-08"
        izz="4.14184164228595E-05" />
    </inertial>
    <visual>
      <origin
        xyz="0 0 0"
        rpy="0 0 0" />
      <geometry>
        <mesh
          filename="package://bumperbot_description/meshes/laser_link.STL" />
      </geometry>
      <material
        name="">
        <color
          rgba="0.792156862745098 0.819607843137255 0.933333333333333 1" />
      </material>
    </visual>
    <collision>
      <origin
        xyz="0 0 0"
        rpy="0 0 0" />
      <geometry>
        <mesh
          filename="package://bumperbot_description/meshes/laser_link.STL" />
      </geometry>
    </collision>
  </link>
  <joint
    name="laser_joint"
    type="fixed">
    <origin
      xyz="-0.0050526 -0.0023221 0.1208"
      rpy="0 0 0" />
    <parent
      link="base_link" />
    <child
      link="laser_link" />
    <axis
      xyz="0 0 0" />
  </joint>
  <link
    name="imu_link">
    <inertial>
      <origin
        xyz="-0.00552433659106688 0.000168210391520346 0.000514000497342681"
        rpy="0 0 0" />
      <mass
        value="0.000528415362211671" />
      <inertia
        ixx="1.46176048428261E-08"
        ixy="1.40015117949421E-10"
        ixz="-1.99633872937403E-12"
        iyy="8.59662482954888E-09"
        iyz="7.52375112767959E-12"
        izz="2.30279421279312E-08" />
    </inertial>
    <visual>
      <origin
        xyz="0 0 0"
        rpy="0 0 0" />
      <geometry>
        <mesh
          filename="package://bumperbot_description/meshes/imu_link.STL" />
      </geometry>
      <material
        name="">
        <color
          rgba="0.792156862745098 0.819607843137255 0.933333333333333 1" />
      </material>
    </visual>
    <collision>
      <origin
        xyz="0 0 0"
        rpy="0 0 0" />
      <geometry>
        <mesh
          filename="package://bumperbot_description/meshes/imu_link.STL" />
      </geometry>
    </collision>
  </link>
  <joint
    name="imu_joint"
    type="fixed">
    <origin
      xyz="0 0 0.0698986241758014"
      rpy="3.14159265358979 0 0" />
    <parent
      link="base_link" />
    <child
      link="imu_link" />
    <axis
      xyz="0 0 0" />
  </joint>

  <transmission name="wheel_right_transmission">
    <type>transmission_interface/SimpleTransmission</type>
    <joint name="wheel_right_joint" >
      <hardwareInterface>hardware_interface/VelocityJointInterface</hardwareInterface>
    </joint>
    <actuator name="wheel_right_motor" >
      <hardwareInterface>hardware_interface/VelocityJointInterface</hardwareInterface>
      <mechanicalReduction>1.0</mechanicalReduction>
    </actuator>
  </transmission>

  <transmission name="wheel_left_transmission">
    <type>transmission_interface/SimpleTransmission</type>
    <joint name="wheel_left_joint" >
      <hardwareInterface>hardware_interface/VelocityJointInterface</hardwareInterface>
    </joint>
    <actuator name="wheel_left_motor" >
      <hardwareInterface>hardware_interface/VelocityJointInterface</hardwareInterface>
      <mechanicalReduction>1.0</mechanicalReduction>
    </actuator>
  </transmission>

  <gazebo reference="base_link">
    <material>Gazebo/DarkGrey</material>
  </gazebo>

  <gazebo reference="wheel_left_link">
    <mu1>0.1</mu1>
    <mu2>0.1</mu2>
    <kp>500000.0</kp>
    <kd>10.0</kd>
    <minDepth>0.001</minDepth>
    <maxVel>0.1</maxVel>
    <fdir1>1 0 0</fdir1>
    <material>Gazebo/Blue</material>
  </gazebo>

  <gazebo reference="wheel_right_link">
    <mu1>0.1</mu1>
    <mu2>0.1</mu2>
    <kp>500000.0</kp>
    <kd>10.0</kd>
    <minDepth>0.001</minDepth>
    <maxVel>0.1</maxVel>
    <fdir1>1 0 0</fdir1>
    <material>Gazebo/Blue</material>
  </gazebo>

  <gazebo reference="caster_rear_link">
    <mu1>0.1</mu1>
    <mu2>0.1</mu2>
    <kp>1000000.0</kp>
    <kd>100.0</kd>
    <minDepth>0.001</minDepth>
    <maxVel>1.0</maxVel>
    <material>Gazebo/FlatBlack</material>
  </gazebo>

  <gazebo reference="caster_front_link">
    <mu1>0.1</mu1>
    <mu2>0.1</mu2>
    <kp>1000000.0</kp>
    <kd>100.0</kd>
    <minDepth>0.001</minDepth>
    <maxVel>1.0</maxVel>
    <material>Gazebo/FlatBlack</material>
  </gazebo>

  <!-- ROS Control -->
  <gazebo>
    <plugin name="gazebo_ros_control" filename="libgazebo_ros_control.so">
      <robotSimType>gazebo_ros_control/DefaultRobotHWSim</robotSimType>
      <legacyModeNS>true</legacyModeNS>
    </plugin>
  </gazebo>

  <!-- Laser Scanner -->
  <gazebo reference="laser_link">
    <material>Gazebo/FlatBlack</material>
    <sensor type="ray" name="lds_lfcd_sensor">
      <pose>0 0 0 0 0 0</pose>
      <visualize>true</visualize>
      <update_rate>5</update_rate>
      <ray>
        <scan>
          <horizontal>
            <samples>360</samples>
            <resolution>1</resolution>
            <min_angle>0.0</min_angle>
            <max_angle>6.28319</max_angle>
          </horizontal>
        </scan>
        <range>
          <min>0.120</min>
          <max>12</max>
          <resolution>0.015</resolution>
        </range>
        <noise>
          <type>gaussian</type>
          <mean>0.0</mean>
          <stddev>0.01</stddev>
        </noise>
      </ray>
      <plugin name="gazebo_ros_lds_lfcd_controller" filename="libgazebo_ros_laser.so">
        <topicName>scan</topicName>
        <frameName>laser_link</frameName>
      </plugin>
    </sensor>
  </gazebo>

</robot>