<?xml version="1.0" encoding="utf-8"?>
<!-- This URDF was automatically created by SolidWorks to URDF Exporter! Originally created by Stephen Brawner (brawner@gmail.com) 
     Commit Version: 1.6.0-4-g7f85cfe  Build Version: 1.6.7995.38578
     For more information, please see http://wiki.ros.org/sw_urdf_exporter -->
<robot
  name="bumperbot_description">
  <link name="base_footprint"/>
  <link
    name="base_link">
    <inertial>
      <origin
        xyz="-0.00200962161040288 -0.002773872071986 0.0152335734876642"
        rpy="0 0 0" />
      <mass
        value="0.0913060531508687" />
      <inertia
        ixx="2.35538590970128E-05"
        ixy="8.03604691787812E-08"
        ixz="-1.30819390431332E-07"
        iyy="9.54188332676489E-06"
        iyz="3.13043067897493E-09"
        izz="2.77334907271241E-05" />
    </inertial>
    <visual>
      <origin
        xyz="0 0 0"
        rpy="0 0 0" />
      <geometry>
        <mesh
          filename="package://bumperbot_description/meshes/base_link.STL" />
      </geometry>
      <material
        name="">
        <color
          rgba="0.258823529411765 0.27843137254902 0.301960784313725 1" />
      </material>
    </visual>
    <collision>
      <origin
        xyz="0 0 0"
        rpy="0 0 0" />
      <geometry>
        <mesh
          filename="package://bumperbot_description/meshes/base_link.STL" />
      </geometry>
    </collision>
  </link>
  <joint name="base_joint" type="fixed">
    <parent link="base_footprint"/>
    <child link="base_link"/>
    <origin xyz="0.0 0.0 0.033" rpy="0 0 0"/>
  </joint>
  <link
    name="wheel_left_link">
    <inertial>
      <origin
        xyz="-3.8757E-05 -0.00067513 0.013705"
        rpy="0 0 0" />
      <mass
        value="0.053009" />
      <inertia
        ixx="1.8789E-05"
        ixy="1.1523E-09"
        ixz="-2.2364E-10"
        iyy="1.883E-05"
        iyz="-4.3552E-10"
        izz="3.1151E-05" />
    </inertial>
    <visual>
      <origin
        xyz="0 0 0"
        rpy="0 0 0" />
      <geometry>
        <mesh
          filename="package://bumperbot_description/meshes/wheel_left_link.STL" />
      </geometry>
      <material
        name="">
        <color
          rgba="0.83137 0.67059 0.12941 1" />
      </material>
    </visual>
    <collision>
      <origin
        xyz="0 0 0"
        rpy="0 0 0" />
      <geometry>
        <mesh
          filename="package://bumperbot_description/meshes/wheel_left_link.STL" />
      </geometry>
    </collision>
  </link>
  <joint
    name="wheel_left_joint"
    type="continuous">
    <origin
      xyz="0 0.07011 0"
      rpy="1.5708 0.26876 -3.1416" />
    <parent
      link="base_link" />
    <child
      link="wheel_left_link" />
    <axis
      xyz="0 0 1" />
  </joint>
  <link
    name="wheel_right_link">
    <inertial>
      <origin
        xyz="2.9582E-05 -0.0006756 0.013705"
        rpy="0 0 0" />
      <mass
        value="0.053009" />
      <inertia
        ixx="1.879E-05"
        ixy="-2.9576E-09"
        ixz="-1.7844E-10"
        iyy="1.883E-05"
        iyz="-4.557E-10"
        izz="3.1151E-05" />
    </inertial>
    <visual>
      <origin
        xyz="0 0 0"
        rpy="0 0 0" />
      <geometry>
        <mesh
          filename="package://bumperbot_description/meshes/wheel_right_link.STL" />
      </geometry>
      <material
        name="">
        <color
          rgba="0.79216 0.81961 0.93333 1" />
      </material>
    </visual>
    <collision>
      <origin
        xyz="0 0 0"
        rpy="0 0 0" />
      <geometry>
        <mesh
          filename="package://bumperbot_description/meshes/wheel_right_link.STL" />
      </geometry>
    </collision>
  </link>
  <joint
    name="wheel_right_joint"
    type="continuous">
    <origin
      xyz="0 -0.07011 0"
      rpy="-1.5708 -1.0554 3.1416" />
    <parent
      link="base_link" />
    <child
      link="wheel_right_link" />
    <axis
      xyz="0 0 1" />
  </joint>
  <link
    name="caster_front_link">
    <inertial>
      <origin
        xyz="0 0 -0.0047625"
        rpy="0 0 0" />
      <mass
        value="4.5247E-07" />
      <inertia
        ixx="4.1051E-12"
        ixy="0"
        ixz="0"
        iyy="4.1051E-12"
        iyz="0"
        izz="4.1051E-12" />
    </inertial>
    <visual>
      <origin
        xyz="0 0 0"
        rpy="0 0 0" />
      <geometry>
        <mesh
          filename="package://bumperbot_description/meshes/caster_front_link.STL" />
      </geometry>
      <material
        name="">
        <color
          rgba="1 0 0 1" />
      </material>
    </visual>
    <collision>
      <origin
        xyz="0 0 0"
        rpy="0 0 0" />
      <geometry>
        <mesh
          filename="package://bumperbot_description/meshes/caster_front_link.STL" />
      </geometry>
    </collision>
  </link>
  <joint
    name="caster_front_joint"
    type="fixed">
    <origin
      xyz="0.042791 0.00016909 -0.024363"
      rpy="1.5708 0 -1.6063" />
    <parent
      link="base_link" />
    <child
      link="caster_front_link" />
    <axis
      xyz="0 0 1" />
  </joint>
  <link
    name="caster_rear_link">
    <inertial>
      <origin
        xyz="0 0 0.0047625"
        rpy="0 0 0" />
      <mass
        value="4.5247E-07" />
      <inertia
        ixx="4.1051E-12"
        ixy="0"
        ixz="0"
        iyy="4.1051E-12"
        iyz="0"
        izz="4.1051E-12" />
    </inertial>
    <visual>
      <origin
        xyz="0 0 0"
        rpy="0 0 0" />
      <geometry>
        <mesh
          filename="package://bumperbot_description/meshes/caster_rear_link.STL" />
      </geometry>
      <material
        name="">
        <color
          rgba="1 0 0 1" />
      </material>
    </visual>
    <collision>
      <origin
        xyz="0 0 0"
        rpy="0 0 0" />
      <geometry>
        <mesh
          filename="package://bumperbot_description/meshes/caster_rear_link.STL" />
      </geometry>
    </collision>
  </link>
  <joint
    name="caster_rear_joint"
    type="fixed">
    <origin
      xyz="-0.042791 -0.00016909 -0.024363"
      rpy="1.5708 0 -1.6063" />
    <parent
      link="base_link" />
    <child
      link="caster_rear_link" />
    <axis
      xyz="0 0 1" />
  </joint>
  <link
    name="camera_link">
    <inertial>
      <origin
        xyz="-0.026854 -0.008234 0.013499"
        rpy="0 0 0" />
      <mass
        value="0.0041086" />
      <inertia
        ixx="3.4464E-07"
        ixy="-1.0176E-07"
        ixz="5.6259E-11"
        iyy="4.8274E-07"
        iyz="-1.1811E-10"
        izz="4.1821E-07" />
    </inertial>
    <visual>
      <origin
        xyz="0 0 0"
        rpy="0 0 0" />
      <geometry>
        <mesh
          filename="package://bumperbot_description/meshes/camera_link.STL" />
      </geometry>
      <material
        name="">
        <color
          rgba="0.79216 0.81961 0.93333 1" />
      </material>
    </visual>
    <collision>
      <origin
        xyz="0 0 0"
        rpy="0 0 0" />
      <geometry>
        <mesh
          filename="package://bumperbot_description/meshes/camera_link.STL" />
      </geometry>
    </collision>
  </link>
  <joint
    name="camera_joint"
    type="fixed">
    <origin
      xyz="0.040774 -0.0135 0.081"
      rpy="1.5708 0 -3.1416" />
    <parent
      link="base_link" />
    <child
      link="camera_link" />
    <axis
      xyz="0 0 0" />
  </joint>
  <link
    name="laser_link">
    <inertial>
      <origin
        xyz="0 0 0"
        rpy="0 0 0" />
      <mass
        value="0" />
      <inertia
        ixx="0"
        ixy="0"
        ixz="0"
        iyy="0"
        iyz="0"
        izz="0" />
    </inertial>
    <visual>
      <origin
        xyz="0 0 0"
        rpy="0 0 0" />
      <geometry>
        <mesh
          filename="package://bumperbot_description/meshes/laser_link.STL" />
      </geometry>
      <material
        name="">
        <color
          rgba="1 1 1 1" />
      </material>
    </visual>
    <collision>
      <origin
        xyz="0 0 0"
        rpy="0 0 0" />
      <geometry>
        <mesh
          filename="package://bumperbot_description/meshes/laser_link.STL" />
      </geometry>
    </collision>
  </link>
  <joint
    name="laser_joint"
    type="fixed">
    <origin
      xyz="-0.0877495976327923 -0.140414680218275 -0.640692319552455"
      rpy="1.5707963267949 0 -3.08450753931019" />
    <parent
      link="base_link" />
    <child
      link="laser_link" />
    <axis
      xyz="0 0 0" />
  </joint>
</robot>